Traceback (most recent call last):
  File "/KernMLOps/python/kernmlops/cli/__init__.py", line 179, in main
    cli.main(prog_name="kernmlops")
  File "/usr/local/lib/python3.12/dist-packages/click/core.py", line 1082, in main
    rv = self.invoke(ctx)
         ^^^^^^^^^^^^^^^^
  File "/usr/local/lib/python3.12/dist-packages/click/core.py", line 1697, in invoke
    return _process_result(sub_ctx.command.invoke(sub_ctx))
                           ^^^^^^^^^^^^^^^^^^^^^^^^^^^^^^^
  File "/usr/local/lib/python3.12/dist-packages/click/core.py", line 1697, in invoke
    return _process_result(sub_ctx.command.invoke(sub_ctx))
                           ^^^^^^^^^^^^^^^^^^^^^^^^^^^^^^^
  File "/usr/local/lib/python3.12/dist-packages/click/core.py", line 1443, in invoke
    return ctx.invoke(self.callback, **ctx.params)
           ^^^^^^^^^^^^^^^^^^^^^^^^^^^^^^^^^^^^^^^
  File "/usr/local/lib/python3.12/dist-packages/click/core.py", line 788, in invoke
    return __callback(*args, **kwargs)
           ^^^^^^^^^^^^^^^^^^^^^^^^^^^
  File "/KernMLOps/python/kernmlops/cli/__init__.py", line 65, in cli_collect_data
    collect.run_collect(
  File "/KernMLOps/python/kernmlops/cli/collect.py", line 105, in run_collect
    raise BenchmarkNotConfiguredError(f"benchmark {benchmark.name()} is not configured")
kernmlops_benchmark.errors.BenchmarkNotConfiguredError: benchmark redis is not configured

make: *** [Makefile:107: collect-data] Error 1
